Workbook

Sheet score_sheet
A1: IT-ITeS SSC NASSCOM
A2: RESULT OF QP BASED ASSESSMENT
A3: Assessment Agency Name | B3: IRIS Corporate Solutions Pvt Ltd
A4: Training Provider Name | B4: Vivan
A5: Qualification Pack Name/Job Role | B5: Trainer (VET and Skills)_V2
A6: Qualification Code | B6: MEP/Q2601
A7: Scheme Name | B7: TTT-TVET
A8: AR ID | B8: Online
A9: Batch ID | B9: =A13 -> 260120260828
A12: Batch ID | B12: Trainee Name | C12: Candidate ID | D12: Gender | E12: Assessment Date | F12: MEP/N2601 - Score 100 | G12: Pass/Fail | H12: MEP/N2602 - Score 100 | I12: Pass/Fail | J12: MEP/N2618 - Score 100 | K12: Pass/Fail | L12: MEP/N2604 - Score 100 | M12: Pass/Fail | N12: MEP/N9903 - Score 100 | O12: Pass/Fail | P12: MEP/N9912 - Score 100 | Q12: Pass/Fail | R12: Total | S12: Overall % | T12: Result of QP (Pass/Fail)
A13: 260120260828 | B13: Bannu Akkabattula | C13: TR499145 | D13: Male | E13: 46241 | F13: 95 | G13: =IF(F13/100*100>=80,"Pass","Fail") -> Pass | H13: 90 | I13: =IF(H13/100*100>=80,"Pass","Fail") -> Pass | J13: 100 | K13: =IF(J13/100*100>=80,"Pass","Fail") -> Pass | L13: 75 | M13: =IF(L13/100*100>=80,"Pass","Fail") -> Fail | N13: 70 | O13: =IF(N13/100*100>=80,"Pass","Fail") -> Fail | P13: 96 | Q13: =IF(P13/100*100>=80,"Pass","Fail") -> Pass | R13: =SUM(F13,H13,J13,L13,N13,P13) -> 526 | S13: =R13/600*100 -> 87.666667 | T13: =IF(S13=0,"ABSENT",IF(S13>=80,"PASS","FAIL")) -> PASS

Sheet Batch Analysis - Tabular
A1: Descriptive Analysis for the Batch
A2: BATCH SUMMARY
A3: Batch Id | B3: =score_sheet!B9 -> 260120260828
A4: Scheme of Assessment | B4: =score_sheet!B7 -> TTT-TVET | D4: Pass Criteria | E4: 0.8
A5: Assessment Date | B5: =score_sheet!E13 -> 46241
A6: QP / Job role | B6: MEP/Q2601 | C6: =score_sheet!B5 -> Trainer (VET and Skills)_V2
A7: QP Result | C7: Total | D7: Gender Wise Analysis | F7: Male | G7: Female
B8: Enrolled | C8: {=COUNTA(_xlfn._xlws.FILTER(score_sheet!A13:A4940,score_sheet!A13:A4940<>""))} -> 1 | F8: =COUNTIF(score_sheet!D13:D1940,"Male") -> 1 | G8: =COUNTIF(score_sheet!D13:D1940,"Female") -> 0
B9: Appeared | C9: {=COUNT(_xlfn._xlws.FILTER(score_sheet!J13:J4940,score_sheet!A13:A4940=B3,score_sheet!J13:J4940<>""))} -> 1 | F9: =COUNTIFS(score_sheet!D12:D13,"Male",score_sheet!T12:T13,"<>ABSENT") -> 1 | G9: =COUNTIFS(score_sheet!D12:D13,"Female",score_sheet!T12:T13,"<>ABSENT") -> 0
B10: Passed | C10: =COUNTIF(score_sheet!T:T,"Pass") -> 1 | F10: =COUNTIFS(score_sheet!D12:D13,"Male",score_sheet!T12:T13,"PASS") -> 1 | G10: =COUNTIFS(score_sheet!D12:D13,"Female",score_sheet!T12:T13,"PASS") -> 0
A11: NOS SUMMARY
B12: % Students Passed (On Appeared) | C12: Mean | D12: Minimum Obtained | E12: Maximum Obtained | F12: Median | G12: SD
A13: MEP/N2601 | B13: =COUNTIFS(score_sheet!G:G,"Pass")/C9 -> 1 | C13: =AVERAGE(score_sheet!F13:F13) -> 95 | D13: =MIN(score_sheet!F13:F13) -> 95 | E13: =MAX(score_sheet!F13:F13) -> 95 | F13: =MEDIAN(score_sheet!F13:F13) -> 95 | G13: =_xlfn.STDEV.S(score_sheet!F13:F13) -> #DIV/0!
A14: MEP/N2602 | B14: =COUNTIFS(score_sheet!I:I,"Pass")/C9 -> 1 | C14: =AVERAGE(score_sheet!H13:H13) -> 90 | D14: =MIN(score_sheet!H13:H13) -> 90 | E14: =MAX(score_sheet!H13:H13) -> 90 | F14: =MEDIAN(score_sheet!H13:H13) -> 90 | G14: =_xlfn.STDEV.S(score_sheet!H13:H13) -> #DIV/0!
A15: MEP/N2618 | B15: =COUNTIFS(score_sheet!K:K,"Pass")/C9 -> 1 | C15: =AVERAGE(score_sheet!J13:J13) -> 100 | D15: =MIN(score_sheet!J13:J13) -> 100 | E15: =MAX(score_sheet!J13:J13) -> 100 | F15: =MEDIAN(score_sheet!J13:J13) -> 100 | G15: =_xlfn.STDEV.S(score_sheet!J13:J13) -> #DIV/0!
A16: MEP/N2604 | B16: =COUNTIFS(score_sheet!M:M,"Pass")/C9 -> 0 | C16: =AVERAGE(score_sheet!L13:L13) -> 75 | D16: =MIN(score_sheet!L13:L13) -> 75 | E16: =MAX(score_sheet!L13:L13) -> 75 | F16: =MEDIAN(score_sheet!L13:L13) -> 75 | G16: =_xlfn.STDEV.S(score_sheet!L13:L13) -> #DIV/0!
A17: MEP/N9903 | B17: =COUNTIFS(score_sheet!O:O,"Pass")/C9 -> 0 | C17: =AVERAGE(score_sheet!N13:N13) -> 70 | D17: =MIN(score_sheet!N13:N13) -> 70 | E17: =MAX(score_sheet!N13:N13) -> 70 | F17: =MEDIAN(score_sheet!N13:N13) -> 70 | G17: =_xlfn.STDEV.S(score_sheet!N13:N13) -> #DIV/0!
A18: MEP/N9912 | B18: =COUNTIFS(score_sheet!Q:Q,"Pass")/C9 -> 1 | C18: =AVERAGE(score_sheet!P13:P13) -> 96 | D18: =MIN(score_sheet!P13:P13) -> 96 | E18: =MAX(score_sheet!P13:P13) -> 96 | F18: =MEDIAN(score_sheet!P13:P13) -> 96 | G18: =_xlfn.STDEV.S(score_sheet!P13:P13) -> #DIV/0!
A19: WEAK PCs (AVERAGE SCORE LESS THAN 50%)
B20: 1 | C20: 2 | D20: 3 | E20: 4 | F20: 5 | G20: 6
A21: MEP/N2601
A25: MEP/N2602
A29: MEP/N2618
A33: MEP/N2604 | B33: PC15 | C33: PC16 | D33: PC17 | E33: PC18 | F33: PC19
A37: MEP/N9903 | B37: PC5 | C37: PC6
A41: MEP/N9912 | B41: PC29 | C41: PC30
A45: Moderately weak PCs (AVERAGE SCORE BETWEEN 50-70%)
A46: MEP/N2601
A50: MEP/N2602 | B50: PC11 | C50: PC12
A54: MEP/N2618
A58: MEP/N2604
A62: MEP/N9903 | B62: PC3 | C62: PC4 | D62: PC7 | E62: PC12 | F62: PC13 | G62: PC15
B63: PC17
A66: MEP/N9912
A71: STRONG PCs (AVERAGE SCORE MORE THAN 70%)
A72: MEP/N2601 | B72: PC1 | C72: PC2 | D72: PC3 | E72: PC4 | F72: PC5 | G72: PC6
B73: PC7 | C73: PC8 | D73: PC9 | E73: PC10 | F73: PC11 | G73: PC12
B74: PC13 | C74: PC14 | D74: PC15 | E74: PC16
A76: MEP/N2602 | B76: PC1 | C76: PC2 | D76: PC3 | E76: PC4 | F76: PC5 | G76: PC6
B77: PC7 | C77: PC8 | D77: PC9 | E77: PC10 | F77: PC13 | G77: PC14
...

Sheet Batch Analysis - Graph
A1: Batch Id | B1: =score_sheet!B9 -> 260120260828
