Workbook

Sheet Result
A1: IT-ITeS SSC NASSCOM
A2: RESULT OF QP BASED ASSESSMENT
A5: Assessment Agency Name | B5: Skills Mantra Edutech Consulting India Pvt Ltd.
A6: Training Provider Name | B6: Valeur Fabtex Private Limited
A7: Assessor Name & ID | B7: BRAJESH KUMAR PRASAD - AR149968
A8: Qualification Pack Name/Job Role | B8: IT Helpdesk Attendant
A9: State | B9: Bihar
A10: City | B10: Banka
A11: Batch Name | B11: 3790631
A12: Batch ID | B12: 3790631
A14: BatchID | B14: Trainee Name | C14: Enrollment No. | D14: Candidate ID | E14: Email | F14: Gender | G14: Assessment Date | H14: SSC/N0202- Total | I14: Pass/Fail | J14: DGT/VSQ/N0101.- Total | K14: Pass/Fail | L14: QP-Total | M14: Student Achieved % | N14: Result of QP
A15: 3790631 | B15: Gulam Amir Hamja | C15: CAN_040354099 | D15: 40354099 | E15: - | F15: Male | G15: 46189 | H15: 89.5 | I15: =IF(H15>=50,"Pass","Fail") -> Pass | J15: 50 | K15: =IF(J15>=25,"Pass","Fail") -> Pass | L15: =H15+J15 -> 139.5 | M15: =L15/150*100 -> 93 | N15: =IF(M15>=50,"Pass","Fail") -> Pass
A16: 3790631 | B16: Ful Kumari | C16: CAN_040354098 | D16: 40354098 | E16: - | F16: Female | G16: 46189 | H16: 95 | I16: =IF(H16>=50,"Pass","Fail") -> Pass | J16: 50 | K16: =IF(J16>=25,"Pass","Fail") -> Pass | L16: =H16+J16 -> 145 | M16: =L16/150*100 -> 96.666667 | N16: =IF(M16>=50,"Pass","Fail") -> Pass
A17: 3790631 | B17: Nigam Kumari | C17: CAN_040354097 | D17: 40354097 | E17: - | F17: Female | G17: 46189 | H17: 97 | I17: =IF(H17>=50,"Pass","Fail") -> Pass | J17: 50 | K17: =IF(J17>=25,"Pass","Fail") -> Pass | L17: =H17+J17 -> 147 | M17: =L17/150*100 -> 98 | N17: =IF(M17>=50,"Pass","Fail") -> Pass
A18: 3790631 | B18: Goutam Kumar | C18: CAN_040354096 | D18: 40354096 | E18: - | F18: Male | G18: 46189 | H18: 87 | I18: =IF(H18>=50,"Pass","Fail") -> Pass | J18: 31 | K18: =IF(J18>=25,"Pass","Fail") -> Pass | L18: =H18+J18 -> 118 | M18: =L18/150*100 -> 78.666667 | N18: =IF(M18>=50,"Pass","Fail") -> Pass
A19: 3790631 | B19: Amar Kumar | C19: CAN_040354095 | D19: 40354095 | E19: - | F19: Male | G19: 46189 | H19: 96 | I19: =IF(H19>=50,"Pass","Fail") -> Pass | J19: 41 | K19: =IF(J19>=25,"Pass","Fail") -> Pass | L19: =H19+J19 -> 137 | M19: =L19/150*100 -> 91.333333 | N19: =IF(M19>=50,"Pass","Fail") -> Pass
A20: 3790631 | B20: Paras Kumar | C20: CAN_040354094 | D20: 40354094 | E20: - | F20: Male | G20: 46189 | H20: 87 | I20: =IF(H20>=50,"Pass","Fail") -> Pass | J20: 50 | K20: =IF(J20>=25,"Pass","Fail") -> Pass | L20: =H20+J20 -> 137 | M20: =L20/150*100 -> 91.333333 | N20: =IF(M20>=50,"Pass","Fail") -> Pass
A21: 3790631 | B21: Komal Kumari | C21: CAN_040354093 | D21: 40354093 | E21: - | F21: Female | G21: 46189 | H21: 50 | I21: =IF(H21>=50,"Pass","Fail") -> Pass | J21: 14 | K21: =IF(J21>=25,"Pass","Fail") -> Fail | L21: =H21+J21 -> 64 | M21: =L21/150*100 -> 42.666667 | N21: =IF(M21>=50,"Pass","Fail") -> Fail
A22: 3790631 | B22: Nisha Kumari | C22: CAN_040354092 | D22: 40354092 | E22: - | F22: Female | G22: 46189 | H22: 95 | I22: =IF(H22>=50,"Pass","Fail") -> Pass | J22: 36 | K22: =IF(J22>=25,"Pass","Fail") -> Pass | L22: =H22+J22 -> 131 | M22: =L22/150*100 -> 87.333333 | N22: =IF(M22>=50,"Pass","Fail") -> Pass
A23: 3790631 | B23: Sweta Kumari | C23: CAN_040354091 | D23: 40354091 | E23: - | F23: Female | G23: 46189 | H23: 96 | I23: =IF(H23>=50,"Pass","Fail") -> Pass | J23: 45 | K23: =IF(J23>=25,"Pass","Fail") -> Pass | L23: =H23+J23 -> 141 | M23: =L23/150*100 -> 94 | N23: =IF(M23>=50,"Pass","Fail") -> Pass
A24: 3790631 | B24: Happy Kumari | C24: CAN_040354090 | D24: 40354090 | E24: - | F24: Female | G24: 46189 | H24: 96 | I24: =IF(H24>=50,"Pass","Fail") -> Pass | J24: 50 | K24: =IF(J24>=25,"Pass","Fail") -> Pass | L24: =H24+J24 -> 146 | M24: =L24/150*100 -> 97.333333 | N24: =IF(M24>=50,"Pass","Fail") -> Pass

Sheet Analysis-Tabular
A1: Descriptive Analysis for the Batch
A2: BATCH SUMMARY
A3: Batch Id | B3: =Result!B11 -> 3790631
A4: Scheme of Assessment | B4: BSDM | D4: Pass Criteria | E4: Overall 50%
A5: Assessment Date | B5: =Result!G15 -> 46189
A6: QP / Job role | B6: SSC/Q0110 | C6: IT Helpdesk Attendant
A7: QP Result | C7: Total | D7: Gender Wise Analysis | F7: Male | G7: Female | XEY7: No of Pass Students | XEZ7: Out of 30 | XFA7: Percentage Pass
B8: Enrolled | C8: =XEZ12 -> 10 | F8: =COUNTIF(Result!$F$15:$F$24,"Male") -> 4 | G8: =COUNTIF(Result!$F$15:$F$24,"Female") -> 6 | XEY8: SSC/N0202 | XEZ8: =COUNTIF(Result!$I$15:$I$24,"Pass") -> 10 | XFA8: =XEZ8/$XEZ$11 -> 1
B9: Appeared | C9: =XEZ11 -> 10 | F9: =COUNTIFS(Result!$N$15:$N$24,"<>Not Appeared",Result!$F$15:$F$24,"Male") -> 4 | G9: =COUNTIFS(Result!$N$15:$N$24,"<>Not Appeared",Result!$F$15:$F$24,"Female") -> 6 | XEY9: DGT/VSQ/N0102 | XEZ9: =COUNTIF(Result!$K$15:$K$24,"Pass") -> 9 | XFA9: =XEZ9/$XEZ$11 -> 0.9
B10: Passed | C10: =XEZ10 -> 9 | F10: =COUNTIFS(Result!$N$15:$N$24,"Pass",Result!$F$15:$F$24,"Male") -> 4 | G10: =COUNTIFS(Result!$N$15:$N$24,"Pass",Result!$F$15:$F$24,"Female") -> 5 | XEY10: Overall | XEZ10: =COUNTIF(Result!$N$15:$N$24,"Pass") -> 9 | XFA10: =XEZ10/$XEZ$11 -> 0.9
A11: NOS SUMMARY | XEY11: Total No of Students | XEZ11: =COUNTIF(Result!$N$15:$N$24,"Pass")+COUNTIF(Result!$N$15:$N$24,"Fail") -> 10
B12: % Students Passed (On Appeared) | C12: Mean (%) | D12: Minimum Obtained (%) | E12: Maximum Obtained (%) | F12: Median (%) | G12: SD (%) | XEY12: Total No of Enrolled Students | XEZ12: =COUNTA(Result!$N$15:$N$24) -> 10
A13: SSC/N0202 | B13: =XFA8 -> 1 | C13: =AVERAGE(Result!$H$15:$H$24)/100 -> 0.8885 | D13: =MIN(Result!$H$15:$H$24)/100 -> 0.5 | E13: =MAX(Result!$H$15:$H$24)/100 -> 0.97 | F13: =MEDIAN(Result!$H$15:$H$24)/100 -> 0.95 | G13: =_xlfn.STDEV.P(Result!$H$15:$H$24)/100 -> 0.13461148
A14: DGT/VSQ/N0101 | B14: =XFA9 -> 0.9 | C14: =AVERAGE(Result!$J$15:$J$24)/50 -> 0.834 | D14: =MIN(Result!$J$15:$J$24)/50 -> 0.28 | E14: =MAX(Result!$J$15:$J$24)/50 -> 1 | F14: =MEDIAN(Result!$J$15:$J$24)/50 -> 0.95 | G14: =_xlfn.STDEV.P(Result!$J$15:$J$24)/50 -> 0.22539743
A15: SSC/Q0110 | B15: =XFA10 -> 0.9 | C15: =AVERAGE(Result!$L$15:$L$24)/150 -> 0.87033333 | D15: =MIN(Result!L15:L15)/150 -> 0.93 | E15: =MAX(Result!$L$15:$L$24)/150 -> 0.98 | F15: =MEDIAN(Result!$L$15:$L$24)/150 -> 0.92166667 | G15: =_xlfn.STDEV.P(Result!$L$15:$L$24)/150 -> 0.15744099
A16: VERY WEAK PCs (AVERAGE SCORE LESS THAN 50%)
A17: SSC/N0202
A18: DGT/VSQ/N0101 | B18: DGT/VSQ/N0101_PC1|DGT/VSQ/N0101_PC2|DGT/VSQ/N0101_PC3
A19: MODERATELY WEAK PCs (AVERAGE SCORE BETWEEN 50-70%)
A20: SSC/N0202 | B20: SSC/N0202_PC1|SSC/N0202_PC2|SSC/N0202_PC3|SSC/N0202_PC4|SSC/N0202_PC5 | C20: SSC/N0202_PC6|SSC/N0202_PC7|SSC/N0202_PC8|SSC/N0202_PC9|SSC/N0202_PC10|SSC/N0202_PC11
A21: DGT/VSQ/N0101 | B21: DGT/VSQ/N0101_PC4|DGT/VSQ/N0101_PC5
A22: STRONG PCs (AVERAGE SCORE MORE THAN 70%)
A23: SSC/N0202 | B23: SSC/N0202_PC12|SSC/N0202_PC13|SSC/N0202_PC14|SSC/N0202_PC15|SSC/N0202_PC16|SSC/N0202_PC17 | C23: SSC/N0202_PC18|SSC/N0202_PC19|SSC/N0202_PC20|SSC/N0202_PC21|SSC/N0202_PC22
A24: DGT/VSQ/N0101 | B24: DGT/VSQ/N0101_PC6|DGT/VSQ/N0101_PC7|DGT/VSQ/N0101_PC8 | C24: DGT/VSQ/N0101_PC9|DGT/VSQ/N0101_PC10|DGT/VSQ/N0101_PC11

Sheet Analysis - Graph
A1: Batch Id | B1: =Result!B11 -> 3790631

Sheet PC-Wise Mean Med
AO1: 12.5 | AP1: 12.5 | AQ1: 5 | AR1: 2.5 | AS1: 2.5 | AT1: 2.5 | AU1: 10 | AV1: 2.5 | AW1: 10 | AX1: 15 | AY1: 5 | AZ1: 5 | BA1: 5 | BB1: 10 | BC1: 10 | BD1: 5 | BE1: 5 | BF1: 10 | BG1: 5 | BH1: 5 | BI1: 5 | BJ1: 5 | BK1: 2.5 | BL1: 2.5 | BM1: 2.5 | BN1: 2.5 | BO1: 10 | BP1: 5 | BQ1: 10 | BR1: 5 | BS1: 5 | BT1: 2.5 | BU1: 2.5
AO2: =AO3/AO1 -> 0.88 | AP2: =AP3/AP1 -> 0.98 | AQ2: =AQ3/AQ1 -> 0.68333333 | AR2: =AR3/AR1 -> 0.93333333 | AS2: =AS3/AS1 -> 1 | AT2: =AT3/AT1 -> 0.6 | AU2: =AU3/AU1 -> 0.84166667 | AV2: =AV3/AV1 -> 0.9 | ... BU2: =BU3/BU1 -> 0.93333333
AO3: =AVERAGE(AO10:AO68) -> 11 | AP3: =AVERAGE(AP10:AP68) -> 12.25 | AQ3: =AVERAGE(AQ10:AQ68) -> 3.4166667 | AR3: =AVERAGE(AR10:AR68) -> 2.3333333 | AS3: =AVERAGE(AS10:AS68) -> 2.5 | AT3: =AVERAGE(AT10:AT68) -> 1.5 | AU3: =AVERAGE(AU10:AU68) -> 8.4166667 | AV3: =AVERAGE(AV10:AV68) -> 2.25 | ... BU3: =AVERAGE(BU10:BU68) -> 2.3333333
AO4: =MEDIAN(AO10:AO69) -> 12.5 | AP4: =MEDIAN(AP10:AP69) -> 12.5 | AQ4: =MEDIAN(AQ10:AQ69) -> 2.5 | AR4: =MEDIAN(AR10:AR69) -> 2.5 | AS4: =MEDIAN(AS10:AS69) -> 2.5 | AT4: =MEDIAN(AT10:AT69) -> 2.5 | AU4: =MEDIAN(AU10:AU69) -> 7.5 | AV4: =MEDIAN(AV10:AV69) -> 2.5 | ... BU4: =MEDIAN(BU10:BU69) -> 2.5
D5: NOS1 | V5: NOS2 | AF5: NOS3
D6: PC1 | E6: PC2 | F6: PC3 | G6: PC4 | H6: PC5 | I6: PC6 | J6: PC7 | K6: PC8 | L6: PC9 | M6: PC10 | N6: PC11 | O6: PC12 | P6: PC13 | Q6: PC14 | R6: PC15 | S6: PC16 | T6: PC17 | V6: PC1 | W6: PC2 | X6: PC3 | Y6: PC4 | Z6: PC5 | AA6: PC6 | AB6: PC7 | AC6: PC8 | AD6: PC9 | AF6: PC1 | AG6: PC2 | AH6: PC3 | AI6: PC4 | AJ6: PC5 | AK6: PC6 | AL6: PC7
AO7: NOS1 | BF7: NOS2 | BO7: NOS3
AO8: PC1 | AP8: PC2 | AQ8: PC3 | AR8: PC4 | AS8: PC5 | AT8: PC6 | AU8: PC7 | AV8: PC8 | AW8: PC9 | AX8: PC10 | AY8: PC11 | AZ8: PC12 | BA8: PC13 | BB8: PC14 | BC8: PC15 | BD8: PC16 | BE8: PC17 | BF8: PC1 | BG8: PC2 | BH8: PC3 | BI8: PC4 | BJ8: PC5 | BK8: PC6 | BL8: PC7 | BM8: PC8 | BN8: PC9 | BO8: PC1 | BP8: PC2 | BQ8: PC3 | BR8: PC4 | BS8: PC5 | BT8: PC6 | BU8: PC7
B10: Rahul Kumar | C10: Theory | D10: 0 | E10: 0 | F10: 0 | G10: 0 | H10: 0 | I10: 0 | J10: 0 | K10: 0 | L10: 0 | M10: 5 | N10: 0 | O10: 2.5 | P10: 5 | Q10: 10 | R10: 7.5 | S10: 0 | T10: 0 | U10: 30 | V10: 5 | W10: 0 | X10: 5 | Y10: 2.5 | Z10: 0 | AA10: 0 | AB10: 0 | AC10: 0 | AD10: 0 | AE10: 12.5 | AF10: 5 | AG10: 0 | AH10: 5 | AI10: 0 | AJ10: 0 | AK10: 0 | AL10: 0 | AM10: 10 | AO10: =SUM(D10:D11) -> 12.5 | AP10: =SUM(E10:E11) -> 12.5 | AQ10: =SUM(F10:F11) -> 5 | AR10: =SUM(G10:G11) -> 2.5 | AS10: =SUM(H10:H11) -> 2.5 | AT10: =SUM(I10:I11) -> 0 | AU10: =SUM(J10:J11) -> 10 | AV10: =SUM(K10:K11) -> 2.5 | ... BE10: =SUM(T10:T11) -> 5 | BF10: =SUM(V10:V11) -> 10 | BG10: =SUM(W10:W11) -> 5 | BH10: =SUM(X10:X11) -> 5 | BI10: =SUM(Y10:Y11) -> 5 | BJ10: =SUM(Z10:Z11) -> 5 | BK10: =SUM(AA10:AA11) -> 2.5 | BL10: =SUM(AB10:AB11) -> 2.5 | BM10: =SUM(AC10:AC11) -> 2.5 | BN10: =SUM(AD10:AD11) -> 2.5 | BO10: =SUM(AF10:AF11) -> 10 | BP10: =SUM(AG10:AG11) -> 5 | BQ10: =SUM(AH10:AH11) -> 10 | BR10: =SUM(AI10:AI11) -> 5 | BS10: =SUM(AJ10:AJ11) -> 5 | BT10: =SUM(AK10:AK11) -> 2.5 | BU10: =SUM(AL10:AL11) -> 2.5
C11: Practical | D11: 12.5 | E11: 12.5 | F11: 5 | G11: 2.5 | H11: 2.5 | I11: 0 | J11: 10 | K11: 2.5 | L11: 9.6 | M11: 10 | N11: 2.5 | O11: 0 | P11: 0 | Q11: 0 | R11: 0 | S11: 5 | T11: 5 | U11: 79.6 | V11: 5 | W11: 5 | X11: 0 | Y11: 2.5 | Z11: 5 | AA11: 2.5 | AB11: 2.5 | AC11: 2.5 | AD11: 2.5 | AE11: 27.5 | AF11: 5 | AG11: 5 | AH11: 5 | AI11: 5 | AJ11: 5 | AK11: 2.5 | AL11: 2.5 | AM11: 30
B12: Anand Kumar | C12: Theory | D12: 0 | E12: 0 | F12: 0 | G12: 0 | H12: 0 | I12: 0 | J12: 0 | K12: 0 | L12: 0 | M12: 5 | N12: 0 | O12: 5 | P12: 5 | Q12: 10 | R12: 10 | S12: 0 | T12: 0 | U12: 35 | V12: 2.5 | W12: 0 | X12: 2.5 | Y12: 2.5 | Z12: 0 | AA12: 0 | AB12: 0 | AC12: 0 | AD12: 0 | AE12: 7.5 | AF12: 5 | AG12: 0 | AH12: 5 | AI12: 0 | AJ12: 0 | AK12: 0 | AL12: 0 | AM12: 10 | AO12: =SUM(D12:D13) -> 10 | AP12: =SUM(E12:E13) -> 12.5 | AQ12: =SUM(F12:F13) -> 5 | AR12: =SUM(G12:G13) -> 2.5 | AS12: =SUM(H12:H13) -> 2.5 | AT12: =SUM(I12:I13) -> 2.5 | AU12: =SUM(J12:J13) -> 10 | AV12: =SUM(K12:K13) -> 2.5 | ... BE12: =SUM(T12:T13) -> 5 | BF12: =SUM(V12:V13) -> 5 | BG12: =SUM(W12:W13) -> 5 | BH12: =SUM(X12:X13) -> 2.5 | BI12: =SUM(Y12:Y13) -> 5 | BJ12: =SUM(Z12:Z13) -> 5 | BK12: =SUM(AA12:AA13) -> 2.5 | BL12: =SUM(AB12:AB13) -> 2.5 | BM12: =SUM(AC12:AC13) -> 2.5 | BN12: =SUM(AD12:AD13) -> 2.5 | BO12: =SUM(AF12:AF13) -> 10 | BP12: =SUM(AG12:AG13) -> 5 | BQ12: =SUM(AH12:AH13) -> 10 | BR12: =SUM(AI12:AI13) -> 2.5 | BS12: =SUM(AJ12:AJ13) -> 5 | BT12: =SUM(AK12:AK13) -> 2.5 | BU12: =SUM(AL12:AL13) -> 2.5
C13: Practical | D13: 10 | E13: 12.5 | F13: 5 | G13: 2.5 | H13: 2.5 | I13: 2.5 | J13: 10 | K13: 2.5 | L13: 9.8 | M13: 10 | N13: 2.5 | O13: 0 | P13: 0 | Q13: 0 | R13: 0 | S13: 5 | T13: 5 | U13: 79.8 | V13: 2.5 | W13: 5 | X13: 0 | Y13: 2.5 | Z13: 5 | AA13: 2.5 | AB13: 2.5 | AC13: 2.5 | AD13: 2.5 | AE13: 25 | AF13: 5 | AG13: 5 | AH13: 5 | AI13: 2.5 | AJ13: 5 | AK13: 2.5 | AL13: 2.5 | AM13: 27.5
B14: Gyanu Kumar | C14: Theory | D14: 0 | E14: 0 | F14: 0 | G14: 0 | H14: 0 | I14: 0 | J14: 0 | K14: 0 | L14: 0 | M14: 5 | N14: 0 | O14: 5 | P14: 5 | Q14: 10 | R14: 7.5 | S14: 0 | T14: 0 | U14: 32.5 | V14: 5 | W14: 0 | X14: 5 | Y14: 2.5 | Z14: 0 | AA14: 0 | AB14: 0 | AC14: 0 | AD14: 0 | AE14: 12.5 | AF14: 5 | AG14: 0 | AH14: 5 | AI14: 0 | AJ14: 0 | AK14: 0 | AL14: 0 | AM14: 10 | AO14: =SUM(D14:D15) -> 12.5 | AP14: =SUM(E14:E15) -> 12.5 | AQ14: =SUM(F14:F15) -> 2.5 | AR14: =SUM(G14:G15) -> 2.5 | AS14: =SUM(H14:H15) -> 2.5 | AT14: =SUM(I14:I15) -> 0 | AU14: =SUM(J14:J15) -> 7.5 | AV14: =SUM(K14:K15) -> 2.5 | ... BE14: =SUM(T14:T15) -> 5 | BF14: =SUM(V14:V15) -> 10 | BG14: =SUM(W14:W15) -> 5 | BH14: =SUM(X14:X15) -> 5 | BI14: =SUM(Y14:Y15) -> 5 | BJ14: =SUM(Z14:Z15) -> 5 | BK14: =SUM(AA14:AA15) -> 2.5 | BL14: =SUM(AB14:AB15) -> 2.5 | BM14: =SUM(AC14:AC15) -> 2.5 | BN14: =SUM(AD14:AD15) -> 2.5 | BO14: =SUM(AF14:AF15) -> 10 | BP14: =SUM(AG14:AG15) -> 5 | BQ14: =SUM(AH14:AH15) -> 10 | BR14: =SUM(AI14:AI15) -> 2.5 | BS14: =SUM(AJ14:AJ15) -> 5 | BT14: =SUM(AK14:AK15) -> 2.5 | BU14: =SUM(AL14:AL15) -> 2.5
C15: Practical | D15: 12.5 | E15: 12.5 | F15: 2.5 | G15: 2.5 | H15: 2.5 | I15: 0 | J15: 7.5 | K15: 2.5 | L15: 9.9 | M15: 5 | N15: 5 | O15: 0 | P15: 0 | Q15: 0 | R15: 0 | S15: 5 | T15: 5 | U15: 72.4 | V15: 5 | W15: 5 | X15: 0 | Y15: 2.5 | Z15: 5 | AA15: 2.5 | AB15: 2.5 | AC15: 2.5 | AD15: 2.5 | AE15: 27.5 | AF15: 5 | AG15: 5 | AH15: 5 | AI15: 2.5 | AJ15: 5 | AK15: 2.5 | AL15: 2.5 | AM15: 27.5
B16: Amarjeet Kumar | C16: Theory | D16: 0 | E16: 0 | F16: 0 | G16: 0 | H16: 0 | I16: 0 | J16: 0 | K16: 0 | L16: 0 | M16: 5 | N16: 0 | O16: 5 | P16: 5 | Q16: 10 | R16: 10 | S16: 0 | T16: 0 | U16: 35 | V16: 5 | W16: 0 | X16: 5 | Y16: 2.5 | Z16: 0 | AA16: 0 | AB16: 0 | AC16: 0 | AD16: 0 | AE16: 12.5 | AF16: 5 | AG16: 0 | AH16: 5 | AI16: 0 | AJ16: 0 | AK16: 0 | AL16: 0 | AM16: 10 | AO16: =SUM(D16:D17) -> 12.5 | AP16: =SUM(E16:E17) -> 12.5 | AQ16: =SUM(F16:F17) -> 5 | AR16: =SUM(G16:G17) -> 2.5 | AS16: =SUM(H16:H17) -> 2.5 | AT16: =SUM(I16:I17) -> 2.5 | AU16: =SUM(J16:J17) -> 2.5 | AV16: =SUM(K16:K17) -> 2.5 | ... BE16: =SUM(T16:T17) -> 5 | BF16: =SUM(V16:V17) -> 10 | BG16: =SUM(W16:W17) -> 5 | BH16: =SUM(X16:X17) -> 5 | BI16: =SUM(Y16:Y17) -> 5 | BJ16: =SUM(Z16:Z17) -> 5 | BK16: =SUM(AA16:AA17) -> 2.5 | BL16: =SUM(AB16:AB17) -> 0 | BM16: =SUM(AC16:AC17) -> 2.5 | BN16: =SUM(AD16:AD17) -> 2.5 | BO16: =SUM(AF16:AF17) -> 10 | BP16: =SUM(AG16:AG17) -> 2.5 | BQ16: =SUM(AH16:AH17) -> 10 | BR16: =SUM(AI16:AI17) -> 5 | BS16: =SUM(AJ16:AJ17) -> 5 | BT16: =SUM(AK16:AK17) -> 2.5 | BU16: =SUM(AL16:AL17) -> 2.5
C17: Practical | D17: 12.5 | E17: 12.5 | F17: 5 | G17: 2.5 | H17: 2.5 | I17: 2.5 | J17: 2.5 | K17: 2.5 | L17: 9.8 | M17: 10 | N17: 5 | O17: 0 | P17: 0 | Q17: 0 | R17: 0 | S17: 2.5 | T17: 5 | U17: 74.8 | V17: 5 | W17: 5 | X17: 0 | Y17: 2.5 | Z17: 5 | AA17: 2.5 | AB17: 0 | AC17: 2.5 | AD17: 2.5 | AE17: 25 | AF17: 5 | AG17: 2.5 | AH17: 5 | AI17: 5 | AJ17: 5 | AK17: 2.5 | AL17: 2.5 | AM17: 27.5
B18: Karan Kumar | C18: Theory | D18: 0 | E18: 0 | F18: 0 | G18: 0 | H18: 0 | I18: 0 | J18: 0 | K18: 0 | L18: 0 | M18: 5 | N18: 0 | O18: 2.5 | P18: 5 | Q18: 10 | R18: 10 | S18: 0 | T18: 0 | U18: 32.5 | V18: 5 | W18: 0 | X18: 5 | Y18: 2.5 | Z18: 0 | AA18: 0 | AB18: 0 | AC18: 0 | AD18: 0 | AE18: 12.5 | AF18: 5 | AG18: 0 | AH18: 5 | AI18: 0 | AJ18: 0 | AK18: 0 | AL18: 0 | AM18: 10 | AO18: =SUM(D18:D19) -> 12.5 | AP18: =SUM(E18:E19) -> 12.5 | AQ18: =SUM(F18:F19) -> 2.5 | AR18: =SUM(G18:G19) -> 2.5 | AS18: =SUM(H18:H19) -> 2.5 | AT18: =SUM(I18:I19) -> 2.5 | AU18: =SUM(J18:J19) -> 7.5 | AV18: =SUM(K18:K19) -> 2.5 | ... BE18: =SUM(T18:T19) -> 5 | BF18: =SUM(V18:V19) -> 10 | BG18: =SUM(W18:W19) -> 5 | BH18: =SUM(X18:X19) -> 5 | BI18: =SUM(Y18:Y19) -> 5 | BJ18: =SUM(Z18:Z19) -> 5 | BK18: =SUM(AA18:AA19) -> 2.5 | BL18: =SUM(AB18:AB19) -> 2.5 | BM18: =SUM(AC18:AC19) -> 2.5 | BN18: =SUM(AD18:AD19) -> 2.5 | BO18: =SUM(AF18:AF19) -> 10 | BP18: =SUM(AG18:AG19) -> 5 | BQ18: =SUM(AH18:AH19) -> 10 | BR18: =SUM(AI18:AI19) -> 2.5 | BS18: =SUM(AJ18:AJ19) -> 5 | BT18: =SUM(AK18:AK19) -> 2.5 | BU18: =SUM(AL18:AL19) -> 2.5
C19: Practical | D19: 12.5 | E19: 12.5 | F19: 2.5 | G19: 2.5 | H19: 2.5 | I19: 2.5 | J19: 7.5 | K19: 2.5 | L19: 9.7 | M19: 10 | N19: 5 | O19: 0 | P19: 0 | Q19: 0 | R19: 0 | S19: 5 | T19: 5 | U19: 79.7 | V19: 5 | W19: 5 | X19: 0 | Y19: 2.5 | Z19: 5 | AA19: 2.5 | AB19: 2.5 | AC19: 2.5 | AD19: 2.5 | AE19: 27.5 | AF19: 5 | AG19: 5 | AH19: 5 | AI19: 2.5 | AJ19: 5 | AK19: 2.5 | AL19: 2.5 | AM19: 27.5
B20: Subash Kumar Singh | C20: Theory | D20: 0 | E20: 0 | F20: 0 | G20: 0 | H20: 0 | I20: 0 | J20: 0 | K20: 0 | L20: 0 | M20: 5 | N20: 0 | O20: 5 | P20: 5 | Q20: 10 | R20: 7.5 | S20: 0 | T20: 0 | U20: 32.5 | V20: 5 | W20: 0 | X20: 5 | Y20: 2.5 | Z20: 0 | AA20: 0 | AB20: 0 | AC20: 0 | AD20: 0 | AE20: 12.5 | AF20: 2.5 | AG20: 0 | AH20: 5 | AI20: 0 | AJ20: 0 | AK20: 0 | AL20: 0 | AM20: 7.5 | AO20: =SUM(D20:D21) -> 12.5 | AP20: =SUM(E20:E21) -> 10 | AQ20: =SUM(F20:F21) -> 5 | AR20: =SUM(G20:G21) -> 2.5 | AS20: =SUM(H20:H21) -> 2.5 | AT20: =SUM(I20:I21) -> 0 | AU20: =SUM(J20:J21) -> 10 | AV20: =SUM(K20:K21) -> 2.5 | ... BE20: =SUM(T20:T21) -> 5 | BF20: =SUM(V20:V21) -> 10 | BG20: =SUM(W20:W21) -> 5 | BH20: =SUM(X20:X21) -> 5 | BI20: =SUM(Y20:Y21) -> 5 | BJ20: =SUM(Z20:Z21) -> 5 | BK20: =SUM(AA20:AA21) -> 2.5 | BL20: =SUM(AB20:AB21) -> 0 | BM20: =SUM(AC20:AC21) -> 2.5 | BN20: =SUM(AD20:AD21) -> 2.5 | BO20: =SUM(AF20:AF21) -> 7.5 | BP20: =SUM(AG20:AG21) -> 5 | BQ20: =SUM(AH20:AH21) -> 10 | BR20: =SUM(AI20:AI21) -> 2.5 | BS20: =SUM(AJ20:AJ21) -> 5 | BT20: =SUM(AK20:AK21) -> 2.5 | BU20: =SUM(AL20:AL21) -> 2.5
C21: Practical | D21: 12.5 | E21: 10 | F21: 5 | G21: 2.5 | H21: 2.5 | I21: 0 | J21: 10 | K21: 2.5 | L21: 9.5 | M21: 10 | N21: 2.5 | O21: 0 | P21: 0 | Q21: 0 | R21: 0 | S21: 5 | T21: 5 | U21: 77 | V21: 5 | W21: 5 | X21: 0 | Y21: 2.5 | Z21: 5 | AA21: 2.5 | AB21: 0 | AC21: 2.5 | AD21: 2.5 | AE21: 25 | AF21: 5 | AG21: 5 | AH21: 5 | AI21: 2.5 | AJ21: 5 | AK21: 2.5 | AL21: 2.5 | AM21: 27.5
B22: Rahul Kumar Singh | C22: Theory | D22: 0 | E22: 0 | F22: 0 | G22: 0 | H22: 0 | I22: 0 | J22: 0 | K22: 0 | L22: 0 | M22: 5 | N22: 0 | O22: 5 | P22: 5 | Q22: 10 | R22: 10 | S22: 0 | T22: 0 | U22: 35 | V22: 5 | W22: 0 | X22: 5 | Y22: 2.5 | Z22: 0 | AA22: 0 | AB22: 0 | AC22: 0 | AD22: 0 | AE22: 12.5 | AF22: 5 | AG22: 0 | AH22: 5 | AI22: 0 | AJ22: 0 | AK22: 0 | AL22: 0 | AM22: 10 | AO22: =SUM(D22:D23) -> 7.5 | AP22: =SUM(E22:E23) -> 12.5 | AQ22: =SUM(F22:F23) -> 2.5 | AR22: =SUM(G22:G23) -> 2.5 | AS22: =SUM(H22:H23) -> 2.5 | AT22: =SUM(I22:I23) -> 2.5 | AU22: =SUM(J22:J23) -> 10 | AV22: =SUM(K22:K23) -> 2.5 | ... BE22: =SUM(T22:T23) -> 5 | BF22: =SUM(V22:V23) -> 10 | BG22: =SUM(W22:W23) -> 5 | BH22: =SUM(X22:X23) -> 5 | BI22: =SUM(Y22:Y23) -> 5 | BJ22: =SUM(Z22:Z23) -> 5 | BK22: =SUM(AA22:AA23) -> 2.5 | BL22: =SUM(AB22:AB23) -> 2.5 | BM22: =SUM(AC22:AC23) -> 2.5 | BN22: =SUM(AD22:AD23) -> 2.5 | BO22: =SUM(AF22:AF23) -> 10 | BP22: =SUM(AG22:AG23) -> 5 | BQ22: =SUM(AH22:AH23) -> 10 | BR22: =SUM(AI22:AI23) -> 2.5 | BS22: =SUM(AJ22:AJ23) -> 5 | BT22: =SUM(AK22:AK23) -> 2.5 | BU22: =SUM(AL22:AL23) -> 2.5
C23: Practical | D23: 7.5 | E23: 12.5 | F23: 2.5 | G23: 2.5 | H23: 2.5 | I23: 2.5 | J23: 10 | K23: 2.5 | L23: 9.8 | M23: 7.5 | N23: 2.5 | O23: 0 | P23: 0 | Q23: 0 | R23: 0 | S23: 2.5 | T23: 5 | U23: 69.8 | V23: 5 | W23: 5 | X23: 0 | Y23: 2.5 | Z23: 5 | AA23: 2.5 | AB23: 2.5 | AC23: 2.5 | AD23: 2.5 | AE23: 27.5 | AF23: 5 | AG23: 5 | AH23: 5 | AI23: 2.5 | AJ23: 5 | AK23: 2.5 | AL23: 2.5 | AM23: 27.5
B24: Seema Devi | C24: Theory | D24: 0 | E24: 0 | F24: 0 | G24: 0 | H24: 0 | I24: 0 | J24: 0 | K24: 0 | L24: 0 | M24: 5 | N24: 0 | O24: 5 | P24: 5 | Q24: 10 | R24: 10 | S24: 0 | T24: 0 | U24: 35 | V24: 5 | W24: 0 | X24: 5 | Y24: 2.5 | Z24: 0 | AA24: 0 | AB24: 0 | AC24: 0 | AD24: 0 | AE24: 12.5 | AF24: 5 | AG24: 0 | AH24: 5 | AI24: 0 | AJ24: 0 | AK24: 0 | AL24: 0 | AM24: 10 | AO24: =SUM(D24:D25) -> 12.5 | AP24: =SUM(E24:E25) -> 12.5 | AQ24: =SUM(F24:F25) -> 2.5 | AR24: =SUM(G24:G25) -> 2.5 | AS24: =SUM(H24:H25) -> 2.5 | AT24: =SUM(I24:I25) -> 2.5 | AU24: =SUM(J24:J25) -> 10 | AV24: =SUM(K24:K25) -> 2.5 | ... BE24: =SUM(T24:T25) -> 5 | BF24: =SUM(V24:V25) -> 10 | BG24: =SUM(W24:W25) -> 5 | BH24: =SUM(X24:X25) -> 5 | BI24: =SUM(Y24:Y25) -> 5 | BJ24: =SUM(Z24:Z25) -> 5 | BK24: =SUM(AA24:AA25) -> 2.5 | BL24: =SUM(AB24:AB25) -> 2.5 | BM24: =SUM(AC24:AC25) -> 2.5 | BN24: =SUM(AD24:AD25) -> 2.5 | BO24: =SUM(AF24:AF25) -> 10 | BP24: =SUM(AG24:AG25) -> 5 | BQ24: =SUM(AH24:AH25) -> 10 | BR24: =SUM(AI24:AI25) -> 5 | BS24: =SUM(AJ24:AJ25) -> 5 | BT24: =SUM(AK24:AK25) -> 2.5 | BU24: =SUM(AL24:AL25) -> 2.5
C25: Practical | D25: 12.5 | E25: 12.5 | F25: 2.5 | G25: 2.5 | H25: 2.5 | I25: 2.5 | J25: 10 | K25: 2.5 | L25: 9.8 | M25: 10 | N25: 5 | O25: 0 | P25: 0 | Q25: 0 | R25: 0 | S25: 5 | T25: 5 | U25: 82.3 | V25: 5 | W25: 5 | X25: 0 | Y25: 2.5 | Z25: 5 | AA25: 2.5 | AB25: 2.5 | AC25: 2.5 | AD25: 2.5 | AE25: 27.5 | AF25: 5 | AG25: 5 | AH25: 5 | AI25: 5 | AJ25: 5 | AK25: 2.5 | AL25: 2.5 | AM25: 30
B26: Kiran Devi | C26: Theory | D26: 0 | E26: 0 | F26: 0 | G26: 0 | H26: 0 | I26: 0 | J26: 0 | K26: 0 | L26: 0 | M26: 5 | N26: 0 | O26: 5 | P26: 5 | Q26: 10 | R26: 7.5 | S26: 0 | T26: 0 | U26: 32.5 | V26: 5 | W26: 0 | X26: 5 | Y26: 2.5 | Z26: 0 | AA26: 0 | AB26: 0 | AC26: 0 | AD26: 0 | AE26: 12.5 | AF26: 5 | AG26: 0 | AH26: 5 | AI26: 0 | AJ26: 0 | AK26: 0 | AL26: 0 | AM26: 10 | AO26: =SUM(D26:D27) -> 10 | AP26: =SUM(E26:E27) -> 12.5 | AQ26: =SUM(F26:F27) -> 2.5 | AR26: =SUM(G26:G27) -> 2.5 | AS26: =SUM(H26:H27) -> 2.5 | AT26: =SUM(I26:I27) -> 0 | AU26: =SUM(J26:J27) -> 7.5 | AV26: =SUM(K26:K27) -> 2.5 | ... BE26: =SUM(T26:T27) -> 5 | BF26: =SUM(V26:V27) -> 10 | BG26: =SUM(W26:W27) -> 5 | BH26: =SUM(X26:X27) -> 5 | BI26: =SUM(Y26:Y27) -> 5 | BJ26: =SUM(Z26:Z27) -> 5 | BK26: =SUM(AA26:AA27) -> 0 | BL26: =SUM(AB26:AB27) -> 2.5 | BM26: =SUM(AC26:AC27) -> 2.5 | BN26: =SUM(AD26:AD27) -> 2.5 | BO26: =SUM(AF26:AF27) -> 10 | BP26: =SUM(AG26:AG27) -> 2.5 | BQ26: =SUM(AH26:AH27) -> 10 | BR26: =SUM(AI26:AI27) -> 5 | BS26: =SUM(AJ26:AJ27) -> 5 | BT26: =SUM(AK26:AK27) -> 2.5 | BU26: =SUM(AL26:AL27) -> 2.5
C27: Practical | D27: 10 | E27: 12.5 | F27: 2.5 | G27: 2.5 | H27: 2.5 | I27: 0 | J27: 7.5 | K27: 2.5 | L27: 9.8 | M27: 7.5 | N27: 5 | O27: 0 | P27: 0 | Q27: 0 | R27: 0 | S27: 5 | T27: 5 | U27: 72.3 | V27: 5 | W27: 5 | X27: 0 | Y27: 2.5 | Z27: 5 | AA27: 0 | AB27: 2.5 | AC27: 2.5 | AD27: 2.5 | AE27: 25 | AF27: 5 | AG27: 2.5 | AH27: 5 | AI27: 5 | AJ27: 5 | AK27: 2.5 | AL27: 2.5 | AM27: 27.5
B28: Aditay Narayan | C28: Theory | D28: 0 | E28: 0 | F28: 0 | G28: 0 | H28: 0 | I28: 0 | J28: 0 | K28: 0 | L28: 0 | M28: 5 | N28: 0 | O28: 5 | P28: 5 | Q28: 10 | R28: 10 | S28: 0 | T28: 0 | U28: 35 | V28: 5 | W28: 0 | X28: 2.5 | Y28: 2.5 | Z28: 0 | AA28: 0 | AB28: 0 | AC28: 0 | AD28: 0 | AE28: 10 | AF28: 5 | AG28: 0 | AH28: 5 | AI28: 0 | AJ28: 0 | AK28: 0 | AL28: 0 | AM28: 10 | AO28: =SUM(D28:D29) -> 10 | AP28: =SUM(E28:E29) -> 12.5 | AQ28: =SUM(F28:F29) -> 2.5 | AR28: =SUM(G28:G29) -> 2.5 | AS28: =SUM(H28:H29) -> 2.5 | AT28: =SUM(I28:I29) -> 2.5 | AU28: =SUM(J28:J29) -> 7.5 | AV28: =SUM(K28:K29) -> 2.5 | ... BE28: =SUM(T28:T29) -> 5 | BF28: =SUM(V28:V29) -> 10 | BG28: =SUM(W28:W29) -> 5 | BH28: =SUM(X28:X29) -> 2.5 | BI28: =SUM(Y28:Y29) -> 5 | BJ28: =SUM(Z28:Z29) -> 5 | BK28: =SUM(AA28:AA29) -> 2.5 | BL28: =SUM(AB28:AB29) -> 2.5 | BM28: =SUM(AC28:AC29) -> 2.5 | BN28: =SUM(AD28:AD29) -> 2.5 | BO28: =SUM(AF28:AF29) -> 10 | BP28: =SUM(AG28:AG29) -> 5 | BQ28: =SUM(AH28:AH29) -> 10 | BR28: =SUM(AI28:AI29) -> 5 | BS28: =SUM(AJ28:AJ29) -> 5 | BT28: =SUM(AK28:AK29) -> 2.5 | BU28: =SUM(AL28:AL29) -> 2.5
C29: Practical | D29: 10 | E29: 12.5 | F29: 2.5 | G29: 2.5 | H29: 2.5 | I29: 2.5 | J29: 7.5 | K29: 2.5 | L29: 9.8 | M29: 7.5 | N29: 5 | O29: 0 | P29: 0 | Q29: 0 | R29: 0 | S29: 5 | T29: 5 | U29: 74.8 | V29: 5 | W29: 5 | X29: 0 | Y29: 2.5 | Z29: 5 | AA29: 2.5 | AB29: 2.5 | AC29: 2.5 | AD29: 2.5 | AE29: 27.5 | AF29: 5 | AG29: 5 | AH29: 5 | AI29: 5 | AJ29: 5 | AK29: 2.5 | AL29: 2.5 | AM29: 30
B30: Shaniraj Singh | C30: Theory | D30: 0 | E30: 0 | F30: 0 | G30: 0 | H30: 0 | I30: 0 | J30: 0 | K30: 0 | L30: 0 | M30: 5 | N30: 0 | O30: 5 | P30: 5 | Q30: 10 | R30: 10 | S30: 0 | T30: 0 | U30: 35 | V30: 5 | W30: 0 | X30: 5 | Y30: 2.5 | Z30: 0 | AA30: 0 | AB30: 0 | AC30: 0 | AD30: 0 | AE30: 12.5 | AF30: 5 | AG30: 0 | AH30: 5 | AI30: 0 | AJ30: 0 | AK30: 0 | AL30: 0 | AM30: 10 | AO30: =SUM(D30:D31) -> 10 | AP30: =SUM(E30:E31) -> 12.5 | AQ30: =SUM(F30:F31) -> 2.5 | AR30: =SUM(G30:G31) -> 0 | AS30: =SUM(H30:H31) -> 2.5 | AT30: =SUM(I30:I31) -> 2.5 | AU30: =SUM(J30:J31) -> 7.5 | AV30: =SUM(K30:K31) -> 2.5 | ... BE30: =SUM(T30:T31) -> 2.5 | BF30: =SUM(V30:V31) -> 10 | BG30: =SUM(W30:W31) -> 5 | BH30: =SUM(X30:X31) -> 5 | BI30: =SUM(Y30:Y31) -> 5 | BJ30: =SUM(Z30:Z31) -> 5 | BK30: =SUM(AA30:AA31) -> 2.5 | BL30: =SUM(AB30:AB31) -> 2.5 | BM30: =SUM(AC30:AC31) -> 2.5 | BN30: =SUM(AD30:AD31) -> 2.5 | BO30: =SUM(AF30:AF31) -> 10 | BP30: =SUM(AG30:AG31) -> 2.5 | BQ30: =SUM(AH30:AH31) -> 10 | BR30: =SUM(AI30:AI31) -> 2.5 | BS30: =SUM(AJ30:AJ31) -> 5 | BT30: =SUM(AK30:AK31) -> 2.5 | BU30: =SUM(AL30:AL31) -> 2.5
C31: Practical | D31: 10 | E31: 12.5 | F31: 2.5 | G31: 0 | H31: 2.5 | I31: 2.5 | J31: 7.5 | K31: 2.5 | L31: 9.8 | M31: 10 | N31: 5 | O31: 0 | P31: 0 | Q31: 0 | R31: 0 | S31: 5 | T31: 2.5 | U31: 72.3 | V31: 5 | W31: 5 | X31: 0 | Y31: 2.5 | Z31: 5 | AA31: 2.5 | AB31: 2.5 | AC31: 2.5 | AD31: 2.5 | AE31: 27.5 | AF31: 5 | AG31: 2.5 | AH31: 5 | AI31: 2.5 | AJ31: 5 | AK31: 2.5 | AL31: 2.5 | AM31: 25
B32: Pramod Kumar Singh | C32: Theory | D32: 0 | E32: 0 | F32: 0 | G32: 0 | H32: 0 | I32: 0 | J32: 0 | K32: 0 | L32: 0 | M32: 5 | N32: 0 | O32: 5 | P32: 5 | Q32: 10 | R32: 10 | S32: 0 | T32: 0 | U32: 35 | V32: 2.5 | W32: 0 | X32: 5 | Y32: 2.5 | Z32: 0 | AA32: 0 | AB32: 0 | AC32: 0 | AD32: 0 | AE32: 10 | AF32: 5 | AG32: 0 | AH32: 5 | AI32: 0 | AJ32: 0 | AK32: 0 | AL32: 0 | AM32: 10 | AO32: =SUM(D32:D33) -> 10 | AP32: =SUM(E32:E33) -> 12.5 | AQ32: =SUM(F32:F33) -> 5 | AR32: =SUM(G32:G33) -> 2.5 | AS32: =SUM(H32:H33) -> 2.5 | AT32: =SUM(I32:I33) -> 2.5 | AU32: =SUM(J32:J33) -> 7.5 | AV32: =SUM(K32:K33) -> 0 | ... BE32: =SUM(T32:T33) -> 5 | BF32: =SUM(V32:V33) -> 5 | BG32: =SUM(W32:W33) -> 5 | BH32: =SUM(X32:X33) -> 5 | BI32: =SUM(Y32:Y33) -> 5 | BJ32: =SUM(Z32:Z33) -> 5 | BK32: =SUM(AA32:AA33) -> 2.5 | BL32: =SUM(AB32:AB33) -> 0 | BM32: =SUM(AC32:AC33) -> 0 | BN32: =SUM(AD32:AD33) -> 2.5 | BO32: =SUM(AF32:AF33) -> 10 | BP32: =SUM(AG32:AG33) -> 5 | BQ32: =SUM(AH32:AH33) -> 10 | BR32: =SUM(AI32:AI33) -> 5 | BS32: =SUM(AJ32:AJ33) -> 5 | BT32: =SUM(AK32:AK33) -> 0 | BU32: =SUM(AL32:AL33) -> 2.5
C33: Practical | D33: 10 | E33: 12.5 | F33: 5 | G33: 2.5 | H33: 2.5 | I33: 2.5 | J33: 7.5 | K33: 0 | L33: 9.6 | M33: 7.5 | N33: 5 | O33: 0 | P33: 0 | Q33: 0 | R33: 0 | S33: 5 | T33: 5 | U33: 74.6 | V33: 2.5 | W33: 5 | X33: 0 | Y33: 2.5 | Z33: 5 | AA33: 2.5 | AB33: 0 | AC33: 0 | AD33: 2.5 | AE33: 20 | AF33: 5 | AG33: 5 | AH33: 5 | AI33: 5 | AJ33: 5 | AK33: 0 | AL33: 2.5 | AM33: 27.5
B34: Sheru Kumar | C34: Theory | D34: 0 | E34: 0 | F34: 0 | G34: 0 | H34: 0 | I34: 0 | J34: 0 | K34: 0 | L34: 0 | M34: 5 | N34: 0 | O34: 5 | P34: 5 | Q34: 10 | R34: 7.5 | S34: 0 | T34: 0 | U34: 32.5 | V34: 5 | W34: 0 | X34: 2.5 | Y34: 2.5 | Z34: 0 | AA34: 0 | AB34: 0 | AC34: 0 | AD34: 0 | AE34: 10 | AF34: 5 | AG34: 0 | AH34: 5 | AI34: 0 | AJ34: 0 | AK34: 0 | AL34: 0 | AM34: 10 | AO34: =SUM(D34:D35) -> 12.5 | AP34: =SUM(E34:E35) -> 12.5 | AQ34: =SUM(F34:F35) -> 5 | AR34: =SUM(G34:G35) -> 2.5 | AS34: =SUM(H34:H35) -> 2.5 | AT34: =SUM(I34:I35) -> 2.5 | AU34: =SUM(J34:J35) -> 7.5 | AV34: =SUM(K34:K35) -> 2.5 | ... BE34: =SUM(T34:T35) -> 5 | BF34: =SUM(V34:V35) -> 10 | BG34: =SUM(W34:W35) -> 5 | BH34: =SUM(X34:X35) -> 2.5 | BI34: =SUM(Y34:Y35) -> 5 | BJ34: =SUM(Z34:Z35) -> 5 | BK34: =SUM(AA34:AA35) -> 2.5 | BL34: =SUM(AB34:AB35) -> 2.5 | BM34: =SUM(AC34:AC35) -> 2.5 | BN34: =SUM(AD34:AD35) -> 2.5 | BO34: =SUM(AF34:AF35) -> 10 | BP34: =SUM(AG34:AG35) -> 5 | BQ34: =SUM(AH34:AH35) -> 10 | BR34: =SUM(AI34:AI35) -> 5 | BS34: =SUM(AJ34:AJ35) -> 5 | BT34: =SUM(AK34:AK35) -> 2.5 | BU34: =SUM(AL34:AL35) -> 2.5
C35: Practical | D35: 12.5 | E35: 12.5 | F35: 5 | G35: 2.5 | H35: 2.5 | I35: 2.5 | J35: 7.5 | K35: 2.5 | L35: 9.8 | M35: 7.5 | N35: 2.5 | O35: 0 | P35: 0 | Q35: 0 | R35: 0 | S35: 5 | T35: 5 | U35: 77.3 | V35: 5 | W35: 5 | X35: 0 | Y35: 2.5 | Z35: 5 | AA35: 2.5 | AB35: 2.5 | AC35: 2.5 | AD35: 2.5 | AE35: 27.5 | AF35: 5 | AG35: 5 | AH35: 5 | AI35: 5 | AJ35: 5 | AK35: 2.5 | AL35: 2.5 | AM35: 30
B36: Sonu Kumar Yadav | C36: Theory | D36: 0 | E36: 0 | F36: 0 | G36: 0 | H36: 0 | I36: 0 | J36: 0 | K36: 0 | L36: 0 | M36: 2.5 | N36: 0 | O36: 5 | P36: 5 | Q36: 10 | R36: 10 | S36: 0 | T36: 0 | U36: 32.5 | V36: 5 | W36: 0 | X36: 5 | Y36: 2.5 | Z36: 0 | AA36: 0 | AB36: 0 | AC36: 0 | AD36: 0 | AE36: 12.5 | AF36: 5 | AG36: 0 | AH36: 5 | AI36: 0 | AJ36: 0 | AK36: 0 | AL36: 0 | AM36: 10 | AO36: =SUM(D36:D37) -> 10 | AP36: =SUM(E36:E37) -> 12.5 | AQ36: =SUM(F36:F37) -> 2.5 | AR36: =SUM(G36:G37) -> 0 | AS36: =SUM(H36:H37) -> 2.5 | AT36: =SUM(I36:I37) -> 0 | AU36: =SUM(J36:J37) -> 7.5 | AV36: =SUM(K36:K37) -> 2.5 | ... BE36: =SUM(T36:T37) -> 5 | BF36: =SUM(V36:V37) -> 10 | BG36: =SUM(W36:W37) -> 5 | BH36: =SUM(X36:X37) -> 5 | BI36: =SUM(Y36:Y37) -> 5 | BJ36: =SUM(Z36:Z37) -> 5 | BK36: =SUM(AA36:AA37) -> 2.5 | BL36: =SUM(AB36:AB37) -> 2.5 | BM36: =SUM(AC36:AC37) -> 0 | BN36: =SUM(AD36:AD37) -> 2.5 | BO36: =SUM(AF36:AF37) -> 10 | BP36: =SUM(AG36:AG37) -> 2.5 | BQ36: =SUM(AH36:AH37) -> 10 | BR36: =SUM(AI36:AI37) -> 2.5 | BS36: =SUM(AJ36:AJ37) -> 5 | BT36: =SUM(AK36:AK37) -> 2.5 | BU36: =SUM(AL36:AL37) -> 0
C37: Practical | D37: 10 | E37: 12.5 | F37: 2.5 | G37: 0 | H37: 2.5 | I37: 0 | J37: 7.5 | K37: 2.5 | L37: 9.9 | M37: 10 | N37: 5 | O37: 0 | P37: 0 | Q37: 0 | R37: 0 | S37: 5 | T37: 5 | U37: 72.4 | V37: 5 | W37: 5 | X37: 0 | Y37: 2.5 | Z37: 5 | AA37: 2.5 | AB37: 2.5 | AC37: 0 | AD37: 2.5 | AE37: 25 | AF37: 5 | AG37: 2.5 | AH37: 5 | AI37: 2.5 | AJ37: 5 | AK37: 2.5 | AL37: 0 | AM37: 22.5
B38: Golu Kumar | C38: Theory | D38: 0 | E38: 0 | F38: 0 | G38: 0 | H38: 0 | I38: 0 | J38: 0 | K38: 0 | L38: 0 | M38: 5 | N38: 0 | O38: 5 | P38: 5 | Q38: 10 | R38: 10 | S38: 0 | T38: 0 | U38: 35 | V38: 5 | W38: 0 | X38: 5 | Y38: 2.5 | Z38: 0 | AA38: 0 | AB38: 0 | AC38: 0 | AD38: 0 | AE38: 12.5 | AF38: 5 | AG38: 0 | AH38: 5 | AI38: 0 | AJ38: 0 | AK38: 0 | AL38: 0 | AM38: 10 | AO38: =SUM(D38:D39) -> 12.5 | AP38: =SUM(E38:E39) -> 12.5 | AQ38: =SUM(F38:F39) -> 5 | AR38: =SUM(G38:G39) -> 2.5 | AS38: =SUM(H38:H39) -> 2.5 | AT38: =SUM(I38:I39) -> 0 | AU38: =SUM(J38:J39) -> 7.5 | AV38: =SUM(K38:K39) -> 0 | ... BE38: =SUM(T38:T39) -> 2.5 | BF38: =SUM(V38:V39) -> 10 | BG38: =SUM(W38:W39) -> 5 | BH38: =SUM(X38:X39) -> 5 | BI38: =SUM(Y38:Y39) -> 5 | BJ38: =SUM(Z38:Z39) -> 5 | BK38: =SUM(AA38:AA39) -> 2.5 | BL38: =SUM(AB38:AB39) -> 2.5 | BM38: =SUM(AC38:AC39) -> 2.5 | BN38: =SUM(AD38:AD39) -> 2.5 | BO38: =SUM(AF38:AF39) -> 10 | BP38: =SUM(AG38:AG39) -> 2.5 | BQ38: =SUM(AH38:AH39) -> 10 | BR38: =SUM(AI38:AI39) -> 5 | BS38: =SUM(AJ38:AJ39) -> 5 | BT38: =SUM(AK38:AK39) -> 2.5 | BU38: =SUM(AL38:AL39) -> 2.5
C39: Practical | D39: 12.5 | E39: 12.5 | F39: 5 | G39: 2.5 | H39: 2.5 | I39: 0 | J39: 7.5 | K39: 0 | L39: 9.7 | M39: 7.5 | N39: 5 | O39: 0 | P39: 0 | Q39: 0 | R39: 0 | S39: 5 | T39: 2.5 | U39: 72.2 | V39: 5 | W39: 5 | X39: 0 | Y39: 2.5 | Z39: 5 | AA39: 2.5 | AB39: 2.5 | AC39: 2.5 | AD39: 2.5 | AE39: 27.5 | AF39: 5 | AG39: 2.5 | AH39: 5 | AI39: 5 | AJ39: 5 | AK39: 2.5 | AL39: 2.5 | AM39: 27.5
B40: Simran Kumari | C40: Theory | D40: 0 | E40: 0 | F40: 0 | G40: 0 | H40: 0 | I40: 0 | J40: 0 | K40: 0 | L40: 0 | M40: 5 | N40: 0 | O40: 5 | P40: 5 | Q40: 10 | R40: 7.5 | S40: 0 | T40: 0 | U40: 32.5 | V40: 5 | W40: 0 | X40: 5 | Y40: 2.5 | Z40: 0 | AA40: 0 | AB40: 0 | AC40: 0 | AD40: 0 | AE40: 12.5 | AF40: 5 | AG40: 0 | AH40: 5 | AI40: 0 | AJ40: 0 | AK40: 0 | AL40: 0 | AM40: 10 | AO40: =SUM(D40:D41) -> 10 | AP40: =SUM(E40:E41) -> 12.5 | AQ40: =SUM(F40:F41) -> 5 | AR40: =SUM(G40:G41) -> 2.5 | AS40: =SUM(H40:H41) -> 2.5 | AT40: =SUM(I40:I41) -> 2.5 | AU40: =SUM(J40:J41) -> 10 | AV40: =SUM(K40:K41) -> 2.5 | ... BE40: =SUM(T40:T41) -> 5 | BF40: =SUM(V40:V41) -> 10 | BG40: =SUM(W40:W41) -> 5 | BH40: =SUM(X40:X41) -> 5 | BI40: =SUM(Y40:Y41) -> 5 | BJ40: =SUM(Z40:Z41) -> 5 | BK40: =SUM(AA40:AA41) -> 2.5 | BL40: =SUM(AB40:AB41) -> 0 | BM40: =SUM(AC40:AC41) -> 2.5 | BN40: =SUM(AD40:AD41) -> 2.5 | BO40: =SUM(AF40:AF41) -> 10 | BP40: =SUM(AG40:AG41) -> 2.5 | BQ40: =SUM(AH40:AH41) -> 10 | BR40: =SUM(AI40:AI41) -> 5 | BS40: =SUM(AJ40:AJ41) -> 0 | BT40: =SUM(AK40:AK41) -> 2.5 | BU40: =SUM(AL40:AL41) -> 2.5
C41: Practical | D41: 10 | E41: 12.5 | F41: 5 | G41: 2.5 | H41: 2.5 | I41: 2.5 | J41: 10 | K41: 2.5 | L41: 9.8 | M41: 10 | N41: 5 | O41: 0 | P41: 0 | Q41: 0 | R41: 0 | S41: 5 | T41: 5 | U41: 82.3 | V41: 5 | W41: 5 | X41: 0 | Y41: 2.5 | Z41: 5 | AA41: 2.5 | AB41: 0 | AC41: 2.5 | AD41: 2.5 | AE41: 25 | AF41: 5 | AG41: 2.5 | AH41: 5 | AI41: 5 | AJ41: 0 | AK41: 2.5 | AL41: 2.5 | AM41: 22.5
...

Sheet PC-Wise
A2: NOS | B2: PC | C2: Total | D2: Total Candidates | E2: No of candidate above 70 % | F2: candidate re presenting half of Batch | G2: Week/Strong | H2: Percentage
A3: NOS1 | B3: PC1 | C3: 12.5 | D3: ='Analysis-Tabular'!$C$8 -> 10 | F3: =D3/2 -> 5 | G3: =IF(AND(H3>=50%,H3<=70%),"Moderated",IF(H3<50%,"Weak","Strong")) -> Strong | H3: 0.88
B4: PC2 | C4: 12.5 | D4: ='Analysis-Tabular'!$C$8 -> 10 | F4: =D4/2 -> 5 | G4: =IF(AND(H4>=50%,H4<=70%),"Moderated",IF(H4<50%,"Weak","Strong")) -> Strong | H4: 0.98
B5: PC3 | C5: 5 | D5: ='Analysis-Tabular'!$C$8 -> 10 | F5: =D5/2 -> 5 | G5: =IF(AND(H5>=50%,H5<=70%),"Moderated",IF(H5<50%,"Weak","Strong")) -> Moderated | H5: 0.68333333
B6: PC4 | C6: 2.5 | D6: ='Analysis-Tabular'!$C$8 -> 10 | F6: =D6/2 -> 5 | G6: =IF(AND(H6>=50%,H6<=70%),"Moderated",IF(H6<50%,"Weak","Strong")) -> Strong | H6: 0.93333333
B7: PC5 | C7: 2.5 | D7: ='Analysis-Tabular'!$C$8 -> 10 | F7: =D7/2 -> 5 | G7: =IF(AND(H7>=50%,H7<=70%),"Moderated",IF(H7<50%,"Weak","Strong")) -> Strong | H7: 1
B8: PC6 | C8: 2.5 | D8: ='Analysis-Tabular'!$C$8 -> 10 | F8: =D8/2 -> 5 | G8: =IF(AND(H8>=50%,H8<=70%),"Moderated",IF(H8<50%,"Weak","Strong")) -> Moderated | H8: 0.6
B9: PC7 | C9: 10 | D9: ='Analysis-Tabular'!$C$8 -> 10 | F9: =D9/2 -> 5 | G9: =IF(AND(H9>=50%,H9<=70%),"Moderated",IF(H9<50%,"Weak","Strong")) -> Strong | H9: 0.84166667
B10: PC8 | C10: 2.5 | D10: ='Analysis-Tabular'!$C$8 -> 10 | F10: =D10/2 -> 5 | G10: =IF(AND(H10>=50%,H10<=70%),"Moderated",IF(H10<50%,"Weak","Strong")) -> Strong | H10: 0.9
B11: PC9 | C11: 10 | D11: ='Analysis-Tabular'!$C$8 -> 10 | F11: =D11/2 -> 5 | G11: =IF(AND(H11>=50%,H11<=70%),"Moderated",IF(H11<50%,"Weak","Strong")) -> Strong | H11: 0.97633333
B12: PC10 | C12: 15 | D12: ='Analysis-Tabular'!$C$8 -> 10 | F12: =D12/2 -> 5 | G12: =IF(AND(H12>=50%,H12<=70%),"Moderated",IF(H12<50%,"Weak","Strong")) -> Strong | H12: 0.84444444
B13: PC11 | C13: 5 | D13: ='Analysis-Tabular'!$C$8 -> 10 | F13: =D13/2 -> 5 | G13: =IF(AND(H13>=50%,H13<=70%),"Moderated",IF(H13<50%,"Weak","Strong")) -> Strong | H13: 0.81666667
B14: PC12 | C14: 5 | D14: ='Analysis-Tabular'!$C$8 -> 10 | F14: =D14/2 -> 5 | G14: =IF(AND(H14>=50%,H14<=70%),"Moderated",IF(H14<50%,"Weak","Strong")) -> Strong | H14: 0.9
B15: PC13 | C15: 5 | D15: ='Analysis-Tabular'!$C$8 -> 10 | F15: =D15/2 -> 5 | G15: =IF(AND(H15>=50%,H15<=70%),"Moderated",IF(H15<50%,"Weak","Strong")) -> Strong | H15: 0.98333333
... B19: PC17 | C19: 5 | D19: ='Analysis-Tabular'!$C$8 -> 10 | F19: =D19/2 -> 5 | G19: =IF(AND(H19>=50%,H19<=70%),"Moderated",IF(H19<50%,"Weak","Strong")) -> Strong | H19: 0.95
A20: NOS2 | B20: PC1 | C20: 10 | D20: ='Analysis-Tabular'!$C$8 -> 10 | F20: =D20/2 -> 5 | G20: =IF(AND(H20>=50%,H20<=70%),"Moderated",IF(H20<50%,"Weak","Strong")) -> Strong | H20: 0.93333333
B21: PC2 | C21: 5 | D21: ='Analysis-Tabular'!$C$8 -> 10 | F21: =D21/2 -> 5 | G21: =IF(AND(H21>=50%,H21<=70%),"Moderated",IF(H21<50%,"Weak","Strong")) -> Strong | H21: 1
B22: PC3 | C22: 5 | D22: ='Analysis-Tabular'!$C$8 -> 10 | F22: =D22/2 -> 5 | G22: =IF(AND(H22>=50%,H22<=70%),"Moderated",IF(H22<50%,"Weak","Strong")) -> Strong | H22: 0.95
B23: PC4 | C23: 5 | D23: ='Analysis-Tabular'!$C$8 -> 10 | F23: =D23/2 -> 5 | G23: =IF(AND(H23>=50%,H23<=70%),"Moderated",IF(H23<50%,"Weak","Strong")) -> Strong | H23: 1
B24: PC5 | C24: 5 | D24: ='Analysis-Tabular'!$C$8 -> 10 | F24: =D24/2 -> 5 | G24: =IF(AND(H24>=50%,H24<=70%),"Moderated",IF(H24<50%,"Weak","Strong")) -> Strong | H24: 1
B25: PC6 | C25: 2.5 | D25: ='Analysis-Tabular'!$C$8 -> 10 | F25: =D25/2 -> 5 | G25: =IF(AND(H25>=50%,H25<=70%),"Moderated",IF(H25<50%,"Weak","Strong")) -> Strong | H25: 0.96666667
B26: PC7 | C26: 2.5 | D26: ='Analysis-Tabular'!$C$8 -> 10 | F26: =D26/2 -> 5 | G26: =IF(AND(H26>=50%,H26<=70%),"Moderated",IF(H26<50%,"Weak","Strong")) -> Moderated | H26: 0.66666667
B27: PC8 | C27: 2.5 | D27: ='Analysis-Tabular'!$C$8 -> 10 | F27: =D27/2 -> 5 | G27: =IF(AND(H27>=50%,H27<=70%),"Moderated",IF(H27<50%,"Weak","Strong")) -> Strong | H27: 0.93333333
B28: PC9 | C28: 2.5 | D28: ='Analysis-Tabular'!$C$8 -> 10 | F28: =D28/2 -> 5 | G28: =IF(AND(H28>=50%,H28<=70%),"Moderated",IF(H28<50%,"Weak","Strong")) -> Strong | H28: 1
A29: NOS3 | B29: PC1 | C29: 10 | D29: ='Analysis-Tabular'!$C$8 -> 10 | F29: =D29/2 -> 5 | G29: =IF(AND(H29>=50%,H29<=70%),"Moderated",IF(H29<50%,"Weak","Strong")) -> Strong | H29: 0.95833333
B30: PC2 | C30: 5 | D30: ='Analysis-Tabular'!$C$8 -> 10 | F30: =D30/2 -> 5 | G30: =IF(AND(H30>=50%,H30<=70%),"Moderated",IF(H30<50%,"Weak","Strong")) -> Strong | H30: 0.9
B31: PC3 | C31: 10 | D31: ='Analysis-Tabular'!$C$8 -> 10 | F31: =D31/2 -> 5 | G31: =IF(AND(H31>=50%,H31<=70%),"Moderated",IF(H31<50%,"Weak","Strong")) -> Strong | H31: 1
B32: PC4 | C32: 5 | D32: ='Analysis-Tabular'!$C$8 -> 10 | F32: =D32/2 -> 5 | G32: =IF(AND(H32>=50%,H32<=70%),"Moderated",IF(H32<50%,"Weak","Strong")) -> Strong | H32: 0.78333333
B33: PC5 | C33: 5 | D33: ='Analysis-Tabular'!$C$8 -> 10 | F33: =D33/2 -> 5 | G33: =IF(AND(H33>=50%,H33<=70%),"Moderated",IF(H33<50%,"Weak","Strong")) -> Strong | H33: 0.96666667
B34: PC6 | C34: 2.5 | D34: ='Analysis-Tabular'!$C$8 -> 10 | F34: =D34/2 -> 5 | G34: =IF(AND(H34>=50%,H34<=70%),"Moderated",IF(H34<50%,"Weak","Strong")) -> Strong | H34: 0.9
B35: PC7 | C35: 2.5 | D35: ='Analysis-Tabular'!$C$8 -> 10 | F35: =D35/2 -> 5 | G35: =IF(AND(H35>=50%,H35<=70%),"Moderated",IF(H35<50%,"Weak","Strong")) -> Strong | H35: 0.93333333
