Workbook

Sheet score_sheet
A1: IT-ITeS SSC NASSCOM
A2: RESULT OF QP BASED ASSESSMENT
A3: Assessment Agency Name | B3: IRIS Corporate Solutions Pvt Ltd
A4: Training Provider Name | B4: Mosaic - DDUKK, Chaibasa
A5: Qualification Pack Name/Job Role | B5: Application Developer - Web & Mobile-V3
A6: Qualification Code | B6: SSC/Q8403
A7: Scheme Name | B7: TTT/ MT [L5-7]
A8: AR ID | B8: A-010FA6
A9: Batch ID | B9: =A13 -> 840320260872
A12: Batch ID | B12: Trainee Name | C12: Candidate ID | D12: Gender | E12: Assessment Date | F12: SSC/N8417 | G12: Pass/Fail | H12: SSC/N8451 | I12: Pass/Fail | J12: SSC/N8125 | K12: Pass/Fail | L12: SSC/N8418 | M12: Pass/Fail | N12: SSC/N8323 | O12: Pass/Fail | P12: SSC/N8452 | Q12: Pass/Fail | R12: DGT/VSQ/N0102 | S12: Pass/Fail | T12: SSC/N8414 | U12: Pass/Fail | V12: SSC/N8415 | W12: Pass/Fail | X12: SSC/N8416 | Y12: Pass/Fail | Z12: QP Total | AA12: Overall Pass % | AB12: Result of QP
A13: 840320260872 | B13: Vandana Rajvanshi | C13: TR677063 | D13: Female | E13: 46240 | F13: 93.5 | G13: =IF(F13/100*100>=80,"Pass","Fail") -> Pass | H13: 85.2 | I13: =IF(H13/100*100>=80,"Pass","Fail") -> Pass | J13: 87 | K13: =IF(J13/100*100>=80,"Pass","Fail") -> Pass | L13: 94.5 | M13: =IF(L13/100*100>=80,"Pass","Fail") -> Pass | N13: 91.5 | O13: =IF(N13/100*100>=80,"Pass","Fail") -> Pass | P13: 97 | Q13: =IF(P13/100*100>=80,"Pass","Fail") -> Pass | R13: 50 | S13: =IF(R13/50*100>=80,"Pass","Fail") -> Pass | T13: 95.5 | U13: =IF(T13/100*100>=80,"Pass","Fail") -> Pass | V13: 83.3 | W13: =IF(V13/100*100>=80,"Pass","Fail") -> Pass | X13: 95 | Y13: =IF(X13/100*100>=80,"Pass","Fail") -> Pass | Z13: =SUM(F13,H13,J13,L13,N13,P13,R13,X13,T13,V13) -> 872.5 | AA13: =Z13/950*100 -> 91.842105 | AB13: =IF(AA13=0,"ABSENT",IF(AA13>=80,"PASS","FAIL")) -> PASS

Sheet Batch Analysis - Tabular
A1: Descriptive Analysis for the Batch
A2: BATCH SUMMARY
A3: Batch Id | B3: =score_sheet!B9 -> 840320260872
A4: Scheme of Assessment | B4: =score_sheet!B7 -> TTT/ MT [L5-7] | D4: Pass Criteria | E4: 0.8
A5: Assessment Date | B5: =score_sheet!E13 -> 46240
A6: QP / Job role | B6: =score_sheet!B6 -> SSC/Q8403 | C6: =score_sheet!B5 -> Application Developer - Web & Mobile-V3
A7: QP Result | C7: Total | D7: Gender Wise Analysis | F7: Male | G7: Female
B8: Enrolled | C8: {=COUNTA(_xlfn._xlws.FILTER(score_sheet!A13:A4949,score_sheet!A13:A4949<>""))} -> 1 | F8: =COUNTIF(score_sheet!D13:D4949,"Male") -> 0 | G8: =COUNTIF(score_sheet!D13:D4949,"Female") -> 1
B9: Appeared | C9: {=COUNT(_xlfn._xlws.FILTER(score_sheet!H13:H4949,score_sheet!A13:A4949=B3,score_sheet!H13:H4949<>""))} -> 1 | F9: =COUNTIFS(score_sheet!D:D,"Male",score_sheet!AB:AB,"<>ABSENT") -> 0 | G9: =COUNTIFS(score_sheet!D:D,"Female",score_sheet!AB:AB,"<>ABSENT") -> 1
B10: Passed | C10: =COUNTIF(score_sheet!AB:AB,"Pass") -> 1 | F10: =COUNTIFS(score_sheet!D:D,"Male",score_sheet!AB:AB,"PASS") -> 0 | G10: =COUNTIFS(score_sheet!D:D,"Female",score_sheet!AB:AB,"PASS") -> 1
A11: NOS SUMMARY
B12: % Students Passed (On Appeared) | C12: Mean | D12: Minimum Obtained | E12: Maximum Obtained | F12: Median | G12: SD
A13: =score_sheet!F12 -> SSC/N8417 | B13: =COUNTIFS(score_sheet!G:G,"Pass")/C9 -> 1 | C13: =AVERAGE(score_sheet!F13:F4949) -> 93.5 | D13: =MIN(score_sheet!F13:F4949) -> 93.5 | E13: =MAX(score_sheet!F13:F4949) -> 93.5 | F13: =MEDIAN(score_sheet!F13:F4949) -> 93.5 | G13: =_xlfn.STDEV.S(score_sheet!F13:F4949) -> #DIV/0!
A14: =score_sheet!H12 -> SSC/N8451 | B14: =COUNTIFS(score_sheet!I:I,"Pass")/C9 -> 1 | C14: =AVERAGE(score_sheet!H13:H4949) -> 85.2 | D14: =MIN(score_sheet!H13:H4949) -> 85.2 | E14: =MAX(score_sheet!H13:H4949) -> 85.2 | F14: =MEDIAN(score_sheet!H13:H4949) -> 85.2 | G14: =_xlfn.STDEV.S(score_sheet!H13:H4949) -> #DIV/0!
A15: =score_sheet!J12 -> SSC/N8125 | B15: =COUNTIFS(score_sheet!K:K,"Pass")/C9 -> 1 | C15: =AVERAGE(score_sheet!J13:J4949) -> 87 | D15: =MIN(score_sheet!J13:J4949) -> 87 | E15: =MAX(score_sheet!J13:J4949) -> 87 | F15: =MEDIAN(score_sheet!J13:J4949) -> 87 | G15: =_xlfn.STDEV.S(score_sheet!J13:J4949) -> #DIV/0!
A16: =score_sheet!L12 -> SSC/N8418 | B16: =COUNTIFS(score_sheet!M:M,"Pass")/C9 -> 1 | C16: =AVERAGE(score_sheet!L13:L4949) -> 94.5 | D16: =MIN(score_sheet!L13:L4949) -> 94.5 | E16: =MAX(score_sheet!L13:L4949) -> 94.5 | F16: =MEDIAN(score_sheet!L13:L4949) -> 94.5 | G16: =_xlfn.STDEV.S(score_sheet!L13:L4949) -> #DIV/0!
A17: =score_sheet!N12 -> SSC/N8323 | B17: =COUNTIFS(score_sheet!O:O,"Pass")/C9 -> 1 | C17: =AVERAGE(score_sheet!N13:N4949) -> 91.5 | D17: =MIN(score_sheet!N13:N4949) -> 91.5 | E17: =MAX(score_sheet!N13:N4949) -> 91.5 | F17: =MEDIAN(score_sheet!N13:N4949) -> 91.5 | G17: =_xlfn.STDEV.S(score_sheet!N13:N4949) -> #DIV/0!
A18: =score_sheet!P12 -> SSC/N8452 | B18: =COUNTIFS(score_sheet!Q:Q,"Pass")/C9 -> 1 | C18: =AVERAGE(score_sheet!P13:P4950) -> 97 | D18: =MIN(score_sheet!P13:P4950) -> 97 | E18: =MAX(score_sheet!P13:P4950) -> 97 | F18: =MEDIAN(score_sheet!P13:P4950) -> 97 | G18: =_xlfn.STDEV.S(score_sheet!P13:P4950) -> #DIV/0!
A19: =score_sheet!R12 -> DGT/VSQ/N0102 | B19: =COUNTIFS(score_sheet!S:S,"Pass")/C9 -> 1 | C19: =AVERAGE(score_sheet!R13:R4951) -> 50 | D19: =MIN(score_sheet!R13:R4951) -> 50 | E19: =MAX(score_sheet!R13:R4951) -> 50 | F19: =MEDIAN(score_sheet!R13:R4951) -> 50 | G19: =_xlfn.STDEV.S(score_sheet!R13:R4951) -> #DIV/0!
A20: =score_sheet!T12 -> SSC/N8414 | B20: =COUNTIFS(score_sheet!U:U,"Pass")/C9 -> 1 | C20: =AVERAGE(score_sheet!T13:T4952) -> 95.5 | D20: =MIN(score_sheet!T13:T4952) -> 95.5 | E20: =MAX(score_sheet!T13:T4952) -> 95.5 | F20: =MEDIAN(score_sheet!T13:T4952) -> 95.5 | G20: =_xlfn.STDEV.S(score_sheet!T13:T4952) -> #DIV/0!
A21: =score_sheet!V12 -> SSC/N8415 | B21: =COUNTIFS(score_sheet!W:W,"Pass")/C9 -> 1 | C21: =AVERAGE(score_sheet!V13:V4952) -> 83.3 | D21: =MIN(score_sheet!V13:V4952) -> 83.3 | E21: =MAX(score_sheet!V13:V4952) -> 83.3 | F21: =MEDIAN(score_sheet!V13:V4952) -> 83.3 | G21: =_xlfn.STDEV.S(score_sheet!V13:V4952) -> #DIV/0!
A22: =score_sheet!X12 -> SSC/N8416 | B22: =COUNTIFS(score_sheet!Y:Y,"Pass")/C9 -> 1 | C22: =AVERAGE(score_sheet!X13:X4953) -> 95 | D22: =MIN(score_sheet!X13:X4953) -> 95 | E22: =MAX(score_sheet!X13:X4953) -> 95 | F22: =MEDIAN(score_sheet!X13:X4953) -> 95 | G22: =_xlfn.STDEV.S(score_sheet!X13:X4953) -> #DIV/0!
A23: WEAK PCs (AVERAGE SCORE LESS THAN 50%)
B24: 1 | C24: 2 | D24: 3 | E24: 4 | F24: 5 | G24: 6
A25: =score_sheet!F12 -> SSC/N8417
A29: =score_sheet!H12 -> SSC/N8451
A33: =score_sheet!J12 -> SSC/N8125 | B33: PC18
A37: =score_sheet!L12 -> SSC/N8418
A41: =score_sheet!N12 -> SSC/N8323
A45: =score_sheet!P12 -> SSC/N8452
A49: =score_sheet!R12 -> DGT/VSQ/N0102
A53: =score_sheet!T12 -> SSC/N8414
A57: =score_sheet!V12 -> SSC/N8415 | B57: PC9 | C57: PC12 | D57: PC13 | E57: PC14
A61: =score_sheet!X12 -> SSC/N8416
A65: Moderately weak PCs (AVERAGE SCORE BETWEEN 50-70%)
A66: =score_sheet!F12 -> SSC/N8417
A70: =score_sheet!H12 -> SSC/N8451 | B70: PC2 | C70: PC3 | D70: PC7 | E70: PC8
A74: =score_sheet!J12 -> SSC/N8125 | B74: PC14 | C74: PC15 | D74: PC16 | E74: PC17 | F74: PC19
A78: =score_sheet!L12 -> SSC/N8418 | B78: PC6 | C78: PC7 | D78: PC15
A82: =score_sheet!N12 -> SSC/N8323 | B82: PC1 | C82: PC2
...

Sheet Batch Analysis - Graph
A1: Batch Id | B1: =score_sheet!B9 -> 840320260872
